Workbook

Sheet How to use
A1: TryoutHQ - Test Scenarios
A3: What this is | B3: One row per test case, generated from TEST_SCENARIOS.txt. The .txt stays the source of truth for the detailed wording.
A4: How to run | B4: 1) Run each "Before" case on the OLD build and write what you see in "Before result". 2) Run "After" and "Feature" cases on the NEW build and set Status. 3) Run every "Regression" case on the NEW build.
A5: Status values | B5: Pass / Fail / Blocked / N/A (drop-down). Fail rows turn red, Pass rows green.
A6: Phase | B6: Before = old-build baseline; After = expected result after a change; Feature = full-coverage suite (sections 25-50); Regression = safety net; General = setup/notes.
A7: Verified (sim) | B7: Yes = already seen working in the iOS simulator by the developer. It still needs your own run, and Android is not verified for any row.
A8: Tabs | B8: "All tests" = every case, filterable. "Summary" = live counts per section (formulas).
A9: Not built | B9: Section 19 (guardian shows under Team) is deferred; its rows are for the baseline only.
A10: Payments | B10: Use Stripe TEST mode only. Never test with a real card.

Sheet Summary
A1: Section | B1: Section title | C1: Total | D1: Pass | E1: Fail | F1: Blocked | G1: N/A | H1: Not run | I1: % done
A2: 1 | B2: LOG OUT / DELETE ACCOUNT BLOCKED AT THE BOTTOM (Android) | C2: =COUNTIF('All tests'!$A:$A,A2) | D2: =COUNTIFS('All tests'!$A:$A,$A2,'All tests'!$I:$I,"Pass") | E2: =COUNTIFS('All tests'!$A:$A,$A2,'All tests'!$I:$I,"Fail") | F2: =COUNTIFS('All tests'!$A:$A,$A2,'All tests'!$I:$I,"Blocked") | G2: =COUNTIFS('All tests'!$A:$A,$A2,'All tests'!$I:$I,"N/A") | H2: =C2-SUM(D2:G2) | I2: =IF(C2=0,0,SUM(D2:G2)/C2)
A3: 2 | B3: EXCEL (.xlsx) IMPORT ONLY IMPORTS ONE NAME | C3: =COUNTIF('All tests'!$A:$A,A3) | D3: =COUNTIFS('All tests'!$A:$A,$A3,'All tests'!$I:$I,"Pass") | E3: =COUNTIFS('All tests'!$A:$A,$A3,'All tests'!$I:$I,"Fail") | F3: =COUNTIFS('All tests'!$A:$A,$A3,'All tests'!$I:$I,"Blocked") | G3: =COUNTIFS('All tests'!$A:$A,$A3,'All tests'!$I:$I,"N/A") | H3: =C3-SUM(D3:G3) | I3: =IF(C3=0,0,SUM(D3:G3)/C3)
A4: 3 | B4: CSV / EXCEL IMPORT IS SLOW (20 NAMES) | C4: =COUNTIF('All tests'!$A:$A,A4) | D4: =COUNTIFS('All tests'!$A:$A,$A4,'All tests'!$I:$I,"Pass") | E4: =COUNTIFS('All tests'!$A:$A,$A4,'All tests'!$I:$I,"Fail") | F4: =COUNTIFS('All tests'!$A:$A,$A4,'All tests'!$I:$I,"Blocked") | G4: =COUNTIFS('All tests'!$A:$A,$A4,'All tests'!$I:$I,"N/A") | H4: =C4-SUM(D4:G4) | I4: =IF(C4=0,0,SUM(D4:G4)/C4)
A5: 4 | B5: REGISTRATIONS: SELECT MULTIPLE, "ADD" ONLY SENDS ONE PLAYER (HIGH) | C5: =COUNTIF('All tests'!$A:$A,A5) | D5: =COUNTIFS('All tests'!$A:$A,$A5,'All tests'!$I:$I,"Pass") | E5: =COUNTIFS('All tests'!$A:$A,$A5,'All tests'!$I:$I,"Fail") | F5: =COUNTIFS('All tests'!$A:$A,$A5,'All tests'!$I:$I,"Blocked") | G5: =COUNTIFS('All tests'!$A:$A,$A5,'All tests'!$I:$I,"N/A") | H5: =C5-SUM(D5:G5) | I5: =IF(C5=0,0,SUM(D5:G5)/C5)
A6: 5 | B6: SELECT ALL PLAYERS ON A ROSTER AND DELETE (HIGH) | C6: =COUNTIF('All tests'!$A:$A,A6) | D6: =COUNTIFS('All tests'!$A:$A,$A6,'All tests'!$I:$I,"Pass") | E6: =COUNTIFS('All tests'!$A:$A,$A6,'All tests'!$I:$I,"Fail") | F6: =COUNTIFS('All tests'!$A:$A,$A6,'All tests'!$I:$I,"Blocked") | G6: =COUNTIFS('All tests'!$A:$A,$A6,'All tests'!$I:$I,"N/A") | H6: =C6-SUM(D6:G6) | I6: =IF(C6=0,0,SUM(D6:G6)/C6)
A7: 6 | B7: EDIT BUTTON ON THE EVALUATION TILE | C7: =COUNTIF('All tests'!$A:$A,A7) | D7: =COUNTIFS('All tests'!$A:$A,$A7,'All tests'!$I:$I,"Pass") | E7: =COUNTIFS('All tests'!$A:$A,$A7,'All tests'!$I:$I,"Fail") | F7: =COUNTIFS('All tests'!$A:$A,$A7,'All tests'!$I:$I,"Blocked") | G7: =COUNTIFS('All tests'!$A:$A,$A7,'All tests'!$I:$I,"N/A") | H7: =C7-SUM(D7:G7) | I7: =IF(C7=0,0,SUM(D7:G7)/C7)
A8: 7 | B8: DATA / PERMISSION CHECKS (touching several fixes) | C8: =COUNTIF('All tests'!$A:$A,A8) | D8: =COUNTIFS('All tests'!$A:$A,$A8,'All tests'!$I:$I,"Pass") | E8: =COUNTIFS('All tests'!$A:$A,$A8,'All tests'!$I:$I,"Fail") | F8: =COUNTIFS('All tests'!$A:$A,$A8,'All tests'!$I:$I,"Blocked") | G8: =COUNTIFS('All tests'!$A:$A,$A8,'All tests'!$I:$I,"N/A") | H8: =C8-SUM(D8:G8) | I8: =IF(C8=0,0,SUM(D8:G8)/C8)
A9: 8 | B9: REGRESSION CHECKLIST (run on the NEW build) | C9: =COUNTIF('All tests'!$A:$A,A9) | D9: =COUNTIFS('All tests'!$A:$A,$A9,'All tests'!$I:$I,"Pass") | E9: =COUNTIFS('All tests'!$A:$A,$A9,'All tests'!$I:$I,"Fail") | F9: =COUNTIFS('All tests'!$A:$A,$A9,'All tests'!$I:$I,"Blocked") | G9: =COUNTIFS('All tests'!$A:$A,$A9,'All tests'!$I:$I,"N/A") | H9: =C9-SUM(D9:G9) | I9: =IF(C9=0,0,SUM(D9:G9)/C9)
A10: 10 | B10: EVALUATION SHOWS ON THE WRONG PLACES (team vs standalone) (HIGH) | C10: =COUNTIF('All tests'!$A:$A,A10) | D10: =COUNTIFS('All tests'!$A:$A,$A10,'All tests'!$I:$I,"Pass") | E10: =COUNTIFS('All tests'!$A:$A,$A10,'All tests'!$I:$I,"Fail") | F10: =COUNTIFS('All tests'!$A:$A,$A10,'All tests'!$I:$I,"Blocked") | G10: =COUNTIFS('All tests'!$A:$A,$A10,'All tests'!$I:$I,"N/A") | H10: =C10-SUM(D10:G10) | I10: =IF(C10=0,0,SUM(D10:G10)/C10)
A11: 11 | B11: DRAG AND DROP / TRADE PLAYERS BETWEEN TEAMS ON THE APK (HIGH) | C11: =COUNTIF('All tests'!$A:$A,A11) | D11: =COUNTIFS('All tests'!$A:$A,$A11,'All tests'!$I:$I,"Pass") | E11: =COUNTIFS('All tests'!$A:$A,$A11,'All tests'!$I:$I,"Fail") | F11: =COUNTIFS('All tests'!$A:$A,$A11,'All tests'!$I:$I,"Blocked") | G11: =COUNTIFS('All tests'!$A:$A,$A11,'All tests'!$I:$I,"N/A") | H11: =C11-SUM(D11:G11) | I11: =IF(C11=0,0,SUM(D11:G11)/C11)
A12: 12 | B12: EXTRA REGRESSION CHECKS FOR SECTIONS 10 AND 11 | C12: =COUNTIF('All tests'!$A:$A,A12) | D12: =COUNTIFS('All tests'!$A:$A,$A12,'All tests'!$I:$I,"Pass") | E12: =COUNTIFS('All tests'!$A:$A,$A12,'All tests'!$I:$I,"Fail") | F12: =COUNTIFS('All tests'!$A:$A,$A12,'All tests'!$I:$I,"Blocked") | G12: =COUNTIFS('All tests'!$A:$A,$A12,'All tests'!$I:$I,"N/A") | H12: =C12-SUM(D12:G12) | I12: =IF(C12=0,0,SUM(D12:G12)/C12)
A13: 13 | B13: TEAM SCREEN TITLE: "<TEAM NAME> HUB" | C13: =COUNTIF('All tests'!$A:$A,A13) | D13: =COUNTIFS('All tests'!$A:$A,$A13,'All tests'!$I:$I,"Pass") | E13: =COUNTIFS('All tests'!$A:$A,$A13,'All tests'!$I:$I,"Fail") | F13: =COUNTIFS('All tests'!$A:$A,$A13,'All tests'!$I:$I,"Blocked") | G13: =COUNTIFS('All tests'!$A:$A,$A13,'All tests'!$I:$I,"N/A") | H13: =C13-SUM(D13:G13) | I13: =IF(C13=0,0,SUM(D13:G13)/C13)
... A51: 51 | B51: WEB APP PARITY (branch feat/shawn-feedback-web-parity) | C51: =COUNTIF('All tests'!$A:$A,A51) | D51: =COUNTIFS('All tests'!$A:$A,$A51,'All tests'!$I:$I,"Pass") | E51: =COUNTIFS('All tests'!$A:$A,$A51,'All tests'!$I:$I,"Fail") | F51: =COUNTIFS('All tests'!$A:$A,$A51,'All tests'!$I:$I,"Blocked") | G51: =COUNTIFS('All tests'!$A:$A,$A51,'All tests'!$I:$I,"N/A") | H51: =C51-SUM(D51:G51) | I51: =IF(C51=0,0,SUM(D51:G51)/C51)
B52: TOTAL | C52: =SUM(C2:C51) | D52: =SUM(D2:D51) | E52: =SUM(E2:E51) | F52: =SUM(F2:F51) | G52: =SUM(G2:G51) | H52: =SUM(H2:H51) | I52: =IF(C52=0,0,SUM(D52:G52)/C52)

Sheet All tests
A1: Section | B1: Section title | C1: ID | D1: Phase | E1: Group | F1: Test case | G1: Verified (sim) | H1: Before result | I1: Status | J1: Actual result / notes | K1: Tester | L1: Date | M1: Bug link
A2: 1 | B2: LOG OUT / DELETE ACCOUNT BLOCKED AT THE BOTTOM (Android) | C2: 1.1 | D2: Before | E2: BEFORE | F2: Android, 3-button nav. Profile > scroll to very bottom. Expected (bug): "Log Out" is partly/fully hidden by the nav bar.
A3: 1 | B3: LOG OUT / DELETE ACCOUNT BLOCKED AT THE BOTTOM (Android) | C3: 1.2 | D3: Before | E3: BEFORE | F3: Try to tap the bottom edge of Log Out and Delete Account. Expected (bug): bottom edge is not tappable.
A4: 1 | B4: LOG OUT / DELETE ACCOUNT BLOCKED AT THE BOTTOM (Android) | C4: 1.3 | D4: After | E4: AFTER (expected) | F4: Android 3-button nav: Log Out fully visible with clear space below it, fully tappable.
A5: 1 | B5: LOG OUT / DELETE ACCOUNT BLOCKED AT THE BOTTOM (Android) | C5: 1.4 | D5: After | E5: AFTER (expected) | F5: Android gesture nav: no large empty band at the bottom.
A6: 1 | B6: LOG OUT / DELETE ACCOUNT BLOCKED AT THE BOTTOM (Android) | C6: 1.5 | D6: After | E6: AFTER (expected) | F6: Android 13/14 (no forced edge-to-edge): NO extra blank space added.
A7: 1 | B7: LOG OUT / DELETE ACCOUNT BLOCKED AT THE BOTTOM (Android) | C7: 1.6 | D7: After | E7: AFTER (expected) | F7: Font size 130-200%: Delete Account and Log Out still reachable.
A8: 1 | B8: LOG OUT / DELETE ACCOUNT BLOCKED AT THE BOTTOM (Android) | C8: 1.7 | D8: After | E8: AFTER (expected) | F8: Landscape: nothing hidden behind the side nav bar.
A9: 1 | B9: LOG OUT / DELETE ACCOUNT BLOCKED AT THE BOTTOM (Android) | C9: 1.8 | D9: After | E9: AFTER (expected) | F9: Guardian-only account (some cards hidden): Danger Zone and Log Out still reachable.
A10: 1 | B10: LOG OUT / DELETE ACCOUNT BLOCKED AT THE BOTTOM (Android) | C10: 1.9 | D10: After | E10: AFTER (expected) | F10: Delete Account: dialog appears; Cancel keeps you signed in.
A11: 1 | B11: LOG OUT / DELETE ACCOUNT BLOCKED AT THE BOTTOM (Android) | C11: 1.10 | D11: After | E11: AFTER (expected) | F11: Log Out: shows loading state, ends on login screen.
A12: 1 | B12: LOG OUT / DELETE ACCOUNT BLOCKED AT THE BOTTOM (Android) | C12: 1.11 | D12: After | E12: AFTER (expected) | F12: iPhone: Profile looks unchanged (no new gap).
A13: 1 | B13: LOG OUT / DELETE ACCOUNT BLOCKED AT THE BOTTOM (Android) | C13: 1.12 | D13: After | E13: AFTER (expected) | F13: Other long scroll screens (season settings, team settings, forms ending in Save): last button fully visible, no double padding.
... A47: 4 | B47: REGISTRATIONS: SELECT MULTIPLE, "ADD" ONLY SENDS ONE PLAYER (HIGH) | C47: 4.2 | D47: Before | E47: BEFORE | F47: Tap "Add to Roster" on one of the selected cards, pick a team. Expected (bug): only that ONE player is added.
A48: 4 | B48: REGISTRATIONS: SELECT MULTIPLE, "ADD" ONLY SENDS ONE PLAYER (HIGH) | C48: 4.3 | D48: After | E48: AFTER (expected) | F48: Tick 2 players. Ticked cards read "Add 2 to Roster"; unticked cards still read "Add to Roster". A bar at the bottom shows "2 selected [Clear] [Add 2 to Roster]" and stays visible while scrolling. | G48: Yes
A49: 4 | B49: REGISTRATIONS: SELECT MULTIPLE, "ADD" ONLY SENDS ONE PLAYER (HIGH) | C49: 4.4 | D49: After | E49: AFTER (expected) | F49: Tap the card's "Add 2 to Roster" -> dialog title "Add 2 Players". | G49: Yes
A50: 4 | B50: REGISTRATIONS: SELECT MULTIPLE, "ADD" ONLY SENDS ONE PLAYER (HIGH) | C50: 4.5 | D50: After | E50: AFTER (expected) | F50: Confirm to a TEAM: both players appear on the team roster; team Players badge +2 without a manual refresh.
A51: 4 | B51: REGISTRATIONS: SELECT MULTIPLE, "ADD" ONLY SENDS ONE PLAYER (HIGH) | C51: 4.6 | D51: After | E51: AFTER (expected) | F51: Confirm to an EVALUATION: both appear on that roster.
A52: 4 | B52: REGISTRATIONS: SELECT MULTIPLE, "ADD" ONLY SENDS ONE PLAYER (HIGH) | C52: 4.7 | D52: After | E52: AFTER (expected) | F52: Select All (25) -> add to Team: all 25 land; progress bar reaches 25 of 25; DB team_roster count +25.
A53: 4 | B53: REGISTRATIONS: SELECT MULTIPLE, "ADD" ONLY SENDS ONE PLAYER (HIGH) | C53: 4.8 | D53: After | E53: AFTER (expected) | F53: Same with destination Evaluation: +25.
A54: 4 | B54: REGISTRATIONS: SELECT MULTIPLE, "ADD" ONLY SENDS ONE PLAYER (HIGH) | C54: 4.9 | D54: After | E54: AFTER (expected) | F54: Two siblings (same guardian email) ticked -> both added.
A55: 4 | B55: REGISTRATIONS: SELECT MULTIPLE, "ADD" ONLY SENDS ONE PLAYER (HIGH) | C55: 4.10 | D55: After | E55: AFTER (expected) | F55: Tick a player, DISMISS them, then add: count and result exclude the dismissed player.
A56: 4 | B56: REGISTRATIONS: SELECT MULTIPLE, "ADD" ONLY SENDS ONE PLAYER (HIGH) | C56: 4.11 | D56: After | E56: AFTER (expected) | F56: Tap "Add to Roster" on an UNTICKED card while others are ticked -> adds only that one player (explicit choice).
A57: 4 | B57: REGISTRATIONS: SELECT MULTIPLE, "ADD" ONLY SENDS ONE PLAYER (HIGH) | C57: 4.12 | D57: After | E57: AFTER (expected) | F57: Single player, no selection: "Add to Roster" works as before.
A58: 4 | B58: REGISTRATIONS: SELECT MULTIPLE, "ADD" ONLY SENDS ONE PLAYER (HIGH) | C58: 4.13 | D58: After | E58: AFTER (expected) | F58: Registration profile popup > "Add to Roster" -> adds that one.
A59: 4 | B59: REGISTRATIONS: SELECT MULTIPLE, "ADD" ONLY SENDS ONE PLAYER (HIGH) | C59: 4.14 | D59: After | E59: AFTER (expected) | F59: Free-plan player limit: adding past the limit shows the limit message; nothing partially added.
A60: 4 | B60: REGISTRATIONS: SELECT MULTIPLE, "ADD" ONLY SENDS ONE PLAYER (HIGH) | C60: 4.15 | D60: After | E60: AFTER (expected) | F60: "Clear" empties the selection and hides the bar.
A61: 4 | B61: REGISTRATIONS: SELECT MULTIPLE, "ADD" ONLY SENDS ONE PLAYER (HIGH) | C61: 4.16 | D61: After | E61: AFTER (expected) | F61: Switch to the "All" / "Dismissed" tab -> bar is hidden.
... A65: 5 | B65: SELECT ALL PLAYERS ON A ROSTER AND DELETE (HIGH) | C65: 5.2 | D65: After | E65: AFTER (expected) | F65: "Select" button appears (only when the team has players).
A66: 5 | B66: SELECT ALL PLAYERS ON A ROSTER AND DELETE (HIGH) | C66: 5.3 | D66: After | E66: AFTER (expected) | F66: Tap Select -> Back / Select All / Delete Selected (disabled), checkboxes on every row, per-row Remove hidden. | G66: Yes
A67: 5 | B67: SELECT ALL PLAYERS ON A ROSTER AND DELETE (HIGH) | C67: 5.4 | D67: After | E67: AFTER (expected) | F67: Select All with NO search -> "Delete Selected (N)" where N is the WHOLE team (999 on the test team), not just loaded rows. | G67: Yes
A68: 5 | B68: SELECT ALL PLAYERS ON A ROSTER AND DELETE (HIGH) | C68: 5.5 | D68: After | E68: AFTER (expected) | F68: Tap Delete Selected -> confirmation shows the right count.
A69: 5 | B69: SELECT ALL PLAYERS ON A ROSTER AND DELETE (HIGH) | C69: 5.6 | D69: After | E69: AFTER (expected) | F69: Confirm -> all removed; list empties; Players badge 0; no page refresh needed; DB team_roster rows gone.
A70: 5 | B70: SELECT ALL PLAYERS ON A ROSTER AND DELETE (HIGH) | C70: 5.7 | D70: After | E70: AFTER (expected) | F70: Tap individual rows to select 3, delete -> only those 3 go.
A71: 5 | B71: SELECT ALL PLAYERS ON A ROSTER AND DELETE (HIGH) | C71: 5.8 | D71: After | E71: AFTER (expected) | F71: Search "Smith" then Select All -> selects only the matches shown; deleting removes only those.
A72: 5 | B72: SELECT ALL PLAYERS ON A ROSTER AND DELETE (HIGH) | C72: 5.9 | D72: After | E72: AFTER (expected) | F72: Deselect All returns count to 0 and disables Delete.
A73: 5 | B73: SELECT ALL PLAYERS ON A ROSTER AND DELETE (HIGH) | C73: 5.10 | D73: After | E73: AFTER (expected) | F73: Back exits select mode with nothing deleted.
A74: 5 | B74: SELECT ALL PLAYERS ON A ROSTER AND DELETE (HIGH) | C74: 5.11 | D74: After | E74: AFTER (expected) | F74: Switch tab (Schedule/Evaluations) while in select mode, then return -> select mode is off, nothing selected.
A75: 5 | B75: SELECT ALL PLAYERS ON A ROSTER AND DELETE (HIGH) | C75: 5.12 | D75: After | E75: AFTER (expected) | F75: Airplane mode during delete -> error message; players still shown match what is really on the roster after refresh.
A76: 5 | B76: SELECT ALL PLAYERS ON A ROSTER AND DELETE (HIGH) | C76: 5.13 | D76: After | E76: AFTER (expected) | F76: Delete everyone, then add one player again -> works, empty state shown in between.
...
